2018-04-27 16:14:46.798 +03:00 [Error] Failed executing DbCommand ("85"ms) [Parameters=["@p0='?', @p1='?', @p2='?', @p3='?', @p4='?', @p5='?', @p6='?', @p7='?', @p8='?', @p9='?', @p10='?', @p11='?'"], CommandType='Text', CommandTimeout='30']"
""SET NOCOUNT ON;
DECLARE @inserted0 TABLE ([Id] int, [_Position] [int]);
MERGE [ClientDisability] USING (
VALUES (@p0, @p1, @p2, @p3, @p4, @p5, 0),
(@p6, @p7, @p8, @p9, @p10, @p11, 1)) AS i ([CreateDate], [CreatedBy], [DeleteFlag], [DisabilityId], [PatientEncounterId], [PersonId], _Position) ON 1=0
WHEN NOT MATCHED THEN
INSERT ([CreateDate], [CreatedBy], [DeleteFlag], [DisabilityId], [PatientEncounterId], [PersonId])
VALUES (i.[CreateDate], i.[CreatedBy], i.[DeleteFlag], i.[DisabilityId], i.[PatientEncounterId], i.[PersonId])
OUTPUT INSERTED.[Id], i._Position
INTO @inserted0;

SELECT [t].[Id] FROM [ClientDisability] t
INNER JOIN @inserted0 i ON ([t].[Id] = [i].[Id])
ORDER BY [i].[_Position];"
System.Data.SqlClient.SqlException (0x80131904): The conversion of a datetime2 data type to a datetime data type resulted in an out-of-range value.
The statement has been terminated.
   at System.Data.SqlClient.SqlCommand.<>c.<ExecuteDbDataReaderAsync>b__108_0(Task`1 result)
   at System.Threading.Tasks.ContinuationResultTaskFromResultTask`2.InnerInvoke()
   at System.Threading.ExecutionContext.Run(ExecutionContext executionContext, ContextCallback callback, Object state)
   at System.Threading.Tasks.Task.ExecuteWithThreadLocal(Task& currentTaskSlot)
--- End of stack trace from previous location where exception was thrown ---
   at System.Runtime.ExceptionServices.ExceptionDispatchInfo.Throw()
   at System.Runtime.CompilerServices.TaskAwaiter.HandleNonSuccessAndDebuggerNotification(Task task)
   at System.Runtime.CompilerServices.TaskAwaiter`1.GetResult()
   at Microsoft.EntityFrameworkCore.Storage.Internal.RelationalCommand.<ExecuteAsync>d__17.MoveNext()
ClientConnectionId:15a1dd5c-d565-4be8-af18-99bab27542af
Error Number:242,State:3,Class:16
2018-04-27 16:14:46.940 +03:00 [Error] An exception occurred in the database while saving changes for context type '"IQCare.HTS.Infrastructure.HtsDbContext"'."
""Microsoft.EntityFrameworkCore.DbUpdateException: An error occurred while updating the entries. See the inner exception for details. ---> System.Data.SqlClient.SqlException: The conversion of a datetime2 data type to a datetime data type resulted in an out-of-range value.
The statement has been terminated.
   at System.Data.SqlClient.SqlCommand.<>c.<ExecuteDbDataReaderAsync>b__108_0(Task`1 result)
   at System.Threading.Tasks.ContinuationResultTaskFromResultTask`2.InnerInvoke()
   at System.Threading.ExecutionContext.Run(ExecutionContext executionContext, ContextCallback callback, Object state)
   at System.Threading.Tasks.Task.ExecuteWithThreadLocal(Task& currentTaskSlot)
--- End of stack trace from previous location where exception was thrown ---
   at System.Runtime.ExceptionServices.ExceptionDispatchInfo.Throw()
   at System.Runtime.CompilerServices.TaskAwaiter.HandleNonSuccessAndDebuggerNotification(Task task)
   at System.Runtime.CompilerServices.TaskAwaiter`1.GetResult()
   at Microsoft.EntityFrameworkCore.Storage.Internal.RelationalCommand.<ExecuteAsync>d__17.MoveNext()
--- End of stack trace from previous location where exception was thrown ---
   at System.Runtime.ExceptionServices.ExceptionDispatchInfo.Throw()
   at System.Runtime.CompilerServices.TaskAwaiter.HandleNonSuccessAndDebuggerNotification(Task task)
   at System.Runtime.CompilerServices.TaskAwaiter`1.GetResult()
   at Microsoft.EntityFrameworkCore.Update.ReaderModificationCommandBatch.<ExecuteAsync>d__32.MoveNext()
   --- End of inner exception stack trace ---
   at Microsoft.EntityFrameworkCore.Update.ReaderModificationCommandBatch.<ExecuteAsync>d__32.MoveNext()
--- End of stack trace from previous location where exception was thrown ---
   at System.Runtime.ExceptionServices.ExceptionDispatchInfo.Throw()
   at System.Runtime.CompilerServices.TaskAwaiter.HandleNonSuccessAndDebuggerNotification(Task task)
   at Microsoft.EntityFrameworkCore.Update.Internal.BatchExecutor.<ExecuteAsync>d__10.MoveNext()
--- End of stack trace from previous location where exception was thrown ---
   at System.Runtime.ExceptionServices.ExceptionDispatchInfo.Throw()
   at System.Runtime.CompilerServices.TaskAwaiter.HandleNonSuccessAndDebuggerNotification(Task task)
   at Microsoft.EntityFrameworkCore.Storage.Internal.SqlServerExecutionStrategy.<ExecuteAsync>d__7`2.MoveNext()
--- End of stack trace from previous location where exception was thrown ---
   at System.Runtime.ExceptionServices.ExceptionDispatchInfo.Throw()
   at System.Runtime.CompilerServices.TaskAwaiter.HandleNonSuccessAndDebuggerNotification(Task task)
   at System.Runtime.CompilerServices.TaskAwaiter`1.GetResult()
   at Microsoft.EntityFrameworkCore.ChangeTracking.Internal.StateManager.<SaveChangesAsync>d__61.MoveNext()
--- End of stack trace from previous location where exception was thrown ---
   at System.Runtime.ExceptionServices.ExceptionDispatchInfo.Throw()
   at System.Runtime.CompilerServices.TaskAwaiter.HandleNonSuccessAndDebuggerNotification(Task task)
   at System.Runtime.CompilerServices.TaskAwaiter`1.GetResult()
   at Microsoft.EntityFrameworkCore.ChangeTracking.Internal.StateManager.<SaveChangesAsync>d__59.MoveNext()
--- End of stack trace from previous location where exception was thrown ---
   at System.Runtime.ExceptionServices.ExceptionDispatchInfo.Throw()
   at System.Runtime.CompilerServices.TaskAwaiter.HandleNonSuccessAndDebuggerNotification(Task task)
   at System.Runtime.CompilerServices.TaskAwaiter`1.GetResult()
   at Microsoft.EntityFrameworkCore.DbContext.<SaveChangesAsync>d__48.MoveNext()"
Microsoft.EntityFrameworkCore.DbUpdateException: An error occurred while updating the entries. See the inner exception for details. ---> System.Data.SqlClient.SqlException: The conversion of a datetime2 data type to a datetime data type resulted in an out-of-range value.
The statement has been terminated.
   at System.Data.SqlClient.SqlCommand.<>c.<ExecuteDbDataReaderAsync>b__108_0(Task`1 result)
   at System.Threading.Tasks.ContinuationResultTaskFromResultTask`2.InnerInvoke()
   at System.Threading.ExecutionContext.Run(ExecutionContext executionContext, ContextCallback callback, Object state)
   at System.Threading.Tasks.Task.ExecuteWithThreadLocal(Task& currentTaskSlot)
--- End of stack trace from previous location where exception was thrown ---
   at System.Runtime.ExceptionServices.ExceptionDispatchInfo.Throw()
   at System.Runtime.CompilerServices.TaskAwaiter.HandleNonSuccessAndDebuggerNotification(Task task)
   at System.Runtime.CompilerServices.TaskAwaiter`1.GetResult()
   at Microsoft.EntityFrameworkCore.Storage.Internal.RelationalCommand.<ExecuteAsync>d__17.MoveNext()
--- End of stack trace from previous location where exception was thrown ---
   at System.Runtime.ExceptionServices.ExceptionDispatchInfo.Throw()
   at System.Runtime.CompilerServices.TaskAwaiter.HandleNonSuccessAndDebuggerNotification(Task task)
   at System.Runtime.CompilerServices.TaskAwaiter`1.GetResult()
   at Microsoft.EntityFrameworkCore.Update.ReaderModificationCommandBatch.<ExecuteAsync>d__32.MoveNext()
   --- End of inner exception stack trace ---
   at Microsoft.EntityFrameworkCore.Update.ReaderModificationCommandBatch.<ExecuteAsync>d__32.MoveNext()
--- End of stack trace from previous location where exception was thrown ---
   at System.Runtime.ExceptionServices.ExceptionDispatchInfo.Throw()
   at System.Runtime.CompilerServices.TaskAwaiter.HandleNonSuccessAndDebuggerNotification(Task task)
   at Microsoft.EntityFrameworkCore.Update.Internal.BatchExecutor.<ExecuteAsync>d__10.MoveNext()
--- End of stack trace from previous location where exception was thrown ---
   at System.Runtime.ExceptionServices.ExceptionDispatchInfo.Throw()
   at System.Runtime.CompilerServices.TaskAwaiter.HandleNonSuccessAndDebuggerNotification(Task task)
   at Microsoft.EntityFrameworkCore.Storage.Internal.SqlServerExecutionStrategy.<ExecuteAsync>d__7`2.MoveNext()
--- End of stack trace from previous location where exception was thrown ---
   at System.Runtime.ExceptionServices.ExceptionDispatchInfo.Throw()
   at System.Runtime.CompilerServices.TaskAwaiter.HandleNonSuccessAndDebuggerNotification(Task task)
   at System.Runtime.CompilerServices.TaskAwaiter`1.GetResult()
   at Microsoft.EntityFrameworkCore.ChangeTracking.Internal.StateManager.<SaveChangesAsync>d__61.MoveNext()
--- End of stack trace from previous location where exception was thrown ---
   at System.Runtime.ExceptionServices.ExceptionDispatchInfo.Throw()
   at System.Runtime.CompilerServices.TaskAwaiter.HandleNonSuccessAndDebuggerNotification(Task task)
   at System.Runtime.CompilerServices.TaskAwaiter`1.GetResult()
   at Microsoft.EntityFrameworkCore.ChangeTracking.Internal.StateManager.<SaveChangesAsync>d__59.MoveNext()
--- End of stack trace from previous location where exception was thrown ---
   at System.Runtime.ExceptionServices.ExceptionDispatchInfo.Throw()
   at System.Runtime.CompilerServices.TaskAwaiter.HandleNonSuccessAndDebuggerNotification(Task task)
   at System.Runtime.CompilerServices.TaskAwaiter`1.GetResult()
   at Microsoft.EntityFrameworkCore.DbContext.<SaveChangesAsync>d__48.MoveNext()
2018-04-27 16:14:47.278 +03:00 [Error] An error occurred while updating the entries. See the inner exception for details.
2018-04-27 16:15:15.797 +03:00 [Error] Failed executing DbCommand ("77"ms) [Parameters=["@p0='?', @p1='?', @p2='?', @p3='?', @p4='?', @p5='?', @p6='?', @p7='?', @p8='?', @p9='?', @p10='?', @p11='?'"], CommandType='Text', CommandTimeout='30']"
""SET NOCOUNT ON;
DECLARE @inserted0 TABLE ([Id] int, [_Position] [int]);
MERGE [ClientDisability] USING (
VALUES (@p0, @p1, @p2, @p3, @p4, @p5, 0),
(@p6, @p7, @p8, @p9, @p10, @p11, 1)) AS i ([CreateDate], [CreatedBy], [DeleteFlag], [DisabilityId], [PatientEncounterId], [PersonId], _Position) ON 1=0
WHEN NOT MATCHED THEN
INSERT ([CreateDate], [CreatedBy], [DeleteFlag], [DisabilityId], [PatientEncounterId], [PersonId])
VALUES (i.[CreateDate], i.[CreatedBy], i.[DeleteFlag], i.[DisabilityId], i.[PatientEncounterId], i.[PersonId])
OUTPUT INSERTED.[Id], i._Position
INTO @inserted0;

SELECT [t].[Id] FROM [ClientDisability] t
INNER JOIN @inserted0 i ON ([t].[Id] = [i].[Id])
ORDER BY [i].[_Position];"
System.Data.SqlClient.SqlException (0x80131904): The conversion of a datetime2 data type to a datetime data type resulted in an out-of-range value.
The statement has been terminated.
   at System.Data.SqlClient.SqlCommand.<>c.<ExecuteDbDataReaderAsync>b__108_0(Task`1 result)
   at System.Threading.Tasks.ContinuationResultTaskFromResultTask`2.InnerInvoke()
   at System.Threading.ExecutionContext.Run(ExecutionContext executionContext, ContextCallback callback, Object state)
   at System.Threading.Tasks.Task.ExecuteWithThreadLocal(Task& currentTaskSlot)
--- End of stack trace from previous location where exception was thrown ---
   at System.Runtime.ExceptionServices.ExceptionDispatchInfo.Throw()
   at System.Runtime.CompilerServices.TaskAwaiter.HandleNonSuccessAndDebuggerNotification(Task task)
   at System.Runtime.CompilerServices.TaskAwaiter`1.GetResult()
   at Microsoft.EntityFrameworkCore.Storage.Internal.RelationalCommand.<ExecuteAsync>d__17.MoveNext()
ClientConnectionId:15a1dd5c-d565-4be8-af18-99bab27542af
Error Number:242,State:3,Class:16
2018-04-27 16:15:15.854 +03:00 [Error] An exception occurred in the database while saving changes for context type '"IQCare.HTS.Infrastructure.HtsDbContext"'."
""Microsoft.EntityFrameworkCore.DbUpdateException: An error occurred while updating the entries. See the inner exception for details. ---> System.Data.SqlClient.SqlException: The conversion of a datetime2 data type to a datetime data type resulted in an out-of-range value.
The statement has been terminated.
   at System.Data.SqlClient.SqlCommand.<>c.<ExecuteDbDataReaderAsync>b__108_0(Task`1 result)
   at System.Threading.Tasks.ContinuationResultTaskFromResultTask`2.InnerInvoke()
   at System.Threading.ExecutionContext.Run(ExecutionContext executionContext, ContextCallback callback, Object state)
   at System.Threading.Tasks.Task.ExecuteWithThreadLocal(Task& currentTaskSlot)
--- End of stack trace from previous location where exception was thrown ---
   at System.Runtime.ExceptionServices.ExceptionDispatchInfo.Throw()
   at System.Runtime.CompilerServices.TaskAwaiter.HandleNonSuccessAndDebuggerNotification(Task task)
   at System.Runtime.CompilerServices.TaskAwaiter`1.GetResult()
   at Microsoft.EntityFrameworkCore.Storage.Internal.RelationalCommand.<ExecuteAsync>d__17.MoveNext()
--- End of stack trace from previous location where exception was thrown ---
   at System.Runtime.ExceptionServices.ExceptionDispatchInfo.Throw()
   at System.Runtime.CompilerServices.TaskAwaiter.HandleNonSuccessAndDebuggerNotification(Task task)
   at System.Runtime.CompilerServices.TaskAwaiter`1.GetResult()
   at Microsoft.EntityFrameworkCore.Update.ReaderModificationCommandBatch.<ExecuteAsync>d__32.MoveNext()
   --- End of inner exception stack trace ---
   at Microsoft.EntityFrameworkCore.Update.ReaderModificationCommandBatch.<ExecuteAsync>d__32.MoveNext()
--- End of stack trace from previous location where exception was thrown ---
   at System.Runtime.ExceptionServices.ExceptionDispatchInfo.Throw()
   at System.Runtime.CompilerServices.TaskAwaiter.HandleNonSuccessAndDebuggerNotification(Task task)
   at Microsoft.EntityFrameworkCore.Update.Internal.BatchExecutor.<ExecuteAsync>d__10.MoveNext()
--- End of stack trace from previous location where exception was thrown ---
   at System.Runtime.ExceptionServices.ExceptionDispatchInfo.Throw()
   at System.Runtime.CompilerServices.TaskAwaiter.HandleNonSuccessAndDebuggerNotification(Task task)
   at Microsoft.EntityFrameworkCore.Storage.Internal.SqlServerExecutionStrategy.<ExecuteAsync>d__7`2.MoveNext()
--- End of stack trace from previous location where exception was thrown ---
   at System.Runtime.ExceptionServices.ExceptionDispatchInfo.Throw()
   at System.Runtime.CompilerServices.TaskAwaiter.HandleNonSuccessAndDebuggerNotification(Task task)
   at System.Runtime.CompilerServices.TaskAwaiter`1.GetResult()
   at Microsoft.EntityFrameworkCore.ChangeTracking.Internal.StateManager.<SaveChangesAsync>d__61.MoveNext()
--- End of stack trace from previous location where exception was thrown ---
   at System.Runtime.ExceptionServices.ExceptionDispatchInfo.Throw()
   at System.Runtime.CompilerServices.TaskAwaiter.HandleNonSuccessAndDebuggerNotification(Task task)
   at System.Runtime.CompilerServices.TaskAwaiter`1.GetResult()
   at Microsoft.EntityFrameworkCore.ChangeTracking.Internal.StateManager.<SaveChangesAsync>d__59.MoveNext()
--- End of stack trace from previous location where exception was thrown ---
   at System.Runtime.ExceptionServices.ExceptionDispatchInfo.Throw()
   at System.Runtime.CompilerServices.TaskAwaiter.HandleNonSuccessAndDebuggerNotification(Task task)
   at System.Runtime.CompilerServices.TaskAwaiter`1.GetResult()
   at Microsoft.EntityFrameworkCore.DbContext.<SaveChangesAsync>d__48.MoveNext()"
Microsoft.EntityFrameworkCore.DbUpdateException: An error occurred while updating the entries. See the inner exception for details. ---> System.Data.SqlClient.SqlException: The conversion of a datetime2 data type to a datetime data type resulted in an out-of-range value.
The statement has been terminated.
   at System.Data.SqlClient.SqlCommand.<>c.<ExecuteDbDataReaderAsync>b__108_0(Task`1 result)
   at System.Threading.Tasks.ContinuationResultTaskFromResultTask`2.InnerInvoke()
   at System.Threading.ExecutionContext.Run(ExecutionContext executionContext, ContextCallback callback, Object state)
   at System.Threading.Tasks.Task.ExecuteWithThreadLocal(Task& currentTaskSlot)
--- End of stack trace from previous location where exception was thrown ---
   at System.Runtime.ExceptionServices.ExceptionDispatchInfo.Throw()
   at System.Runtime.CompilerServices.TaskAwaiter.HandleNonSuccessAndDebuggerNotification(Task task)
   at System.Runtime.CompilerServices.TaskAwaiter`1.GetResult()
   at Microsoft.EntityFrameworkCore.Storage.Internal.RelationalCommand.<ExecuteAsync>d__17.MoveNext()
--- End of stack trace from previous location where exception was thrown ---
   at System.Runtime.ExceptionServices.ExceptionDispatchInfo.Throw()
   at System.Runtime.CompilerServices.TaskAwaiter.HandleNonSuccessAndDebuggerNotification(Task task)
   at System.Runtime.CompilerServices.TaskAwaiter`1.GetResult()
   at Microsoft.EntityFrameworkCore.Update.ReaderModificationCommandBatch.<ExecuteAsync>d__32.MoveNext()
   --- End of inner exception stack trace ---
   at Microsoft.EntityFrameworkCore.Update.ReaderModificationCommandBatch.<ExecuteAsync>d__32.MoveNext()
--- End of stack trace from previous location where exception was thrown ---
   at System.Runtime.ExceptionServices.ExceptionDispatchInfo.Throw()
   at System.Runtime.CompilerServices.TaskAwaiter.HandleNonSuccessAndDebuggerNotification(Task task)
   at Microsoft.EntityFrameworkCore.Update.Internal.BatchExecutor.<ExecuteAsync>d__10.MoveNext()
--- End of stack trace from previous location where exception was thrown ---
   at System.Runtime.ExceptionServices.ExceptionDispatchInfo.Throw()
   at System.Runtime.CompilerServices.TaskAwaiter.HandleNonSuccessAndDebuggerNotification(Task task)
   at Microsoft.EntityFrameworkCore.Storage.Internal.SqlServerExecutionStrategy.<ExecuteAsync>d__7`2.MoveNext()
--- End of stack trace from previous location where exception was thrown ---
   at System.Runtime.ExceptionServices.ExceptionDispatchInfo.Throw()
   at System.Runtime.CompilerServices.TaskAwaiter.HandleNonSuccessAndDebuggerNotification(Task task)
   at System.Runtime.CompilerServices.TaskAwaiter`1.GetResult()
   at Microsoft.EntityFrameworkCore.ChangeTracking.Internal.StateManager.<SaveChangesAsync>d__61.MoveNext()
--- End of stack trace from previous location where exception was thrown ---
   at System.Runtime.ExceptionServices.ExceptionDispatchInfo.Throw()
   at System.Runtime.CompilerServices.TaskAwaiter.HandleNonSuccessAndDebuggerNotification(Task task)
   at System.Runtime.CompilerServices.TaskAwaiter`1.GetResult()
   at Microsoft.EntityFrameworkCore.ChangeTracking.Internal.StateManager.<SaveChangesAsync>d__59.MoveNext()
--- End of stack trace from previous location where exception was thrown ---
   at System.Runtime.ExceptionServices.ExceptionDispatchInfo.Throw()
   at System.Runtime.CompilerServices.TaskAwaiter.HandleNonSuccessAndDebuggerNotification(Task task)
   at System.Runtime.CompilerServices.TaskAwaiter`1.GetResult()
   at Microsoft.EntityFrameworkCore.DbContext.<SaveChangesAsync>d__48.MoveNext()
2018-04-27 16:15:16.116 +03:00 [Error] An error occurred while updating the entries. See the inner exception for details.
2018-04-27 16:16:35.237 +03:00 [Error] Failed executing DbCommand ("50"ms) [Parameters=["@p0='?', @p1='?', @p2='?', @p3='?', @p4='?', @p5='?', @p6='?', @p7='?', @p8='?', @p9='?', @p10='?', @p11='?'"], CommandType='Text', CommandTimeout='30']"
""SET NOCOUNT ON;
DECLARE @inserted0 TABLE ([Id] int, [_Position] [int]);
MERGE [ClientDisability] USING (
VALUES (@p0, @p1, @p2, @p3, @p4, @p5, 0),
(@p6, @p7, @p8, @p9, @p10, @p11, 1)) AS i ([CreateDate], [CreatedBy], [DeleteFlag], [DisabilityId], [PatientEncounterId], [PersonId], _Position) ON 1=0
WHEN NOT MATCHED THEN
INSERT ([CreateDate], [CreatedBy], [DeleteFlag], [DisabilityId], [PatientEncounterId], [PersonId])
VALUES (i.[CreateDate], i.[CreatedBy], i.[DeleteFlag], i.[DisabilityId], i.[PatientEncounterId], i.[PersonId])
OUTPUT INSERTED.[Id], i._Position
INTO @inserted0;

SELECT [t].[Id] FROM [ClientDisability] t
INNER JOIN @inserted0 i ON ([t].[Id] = [i].[Id])
ORDER BY [i].[_Position];"
System.Data.SqlClient.SqlException (0x80131904): The conversion of a datetime2 data type to a datetime data type resulted in an out-of-range value.
The statement has been terminated.
   at System.Data.SqlClient.SqlCommand.<>c.<ExecuteDbDataReaderAsync>b__108_0(Task`1 result)
   at System.Threading.Tasks.ContinuationResultTaskFromResultTask`2.InnerInvoke()
   at System.Threading.ExecutionContext.Run(ExecutionContext executionContext, ContextCallback callback, Object state)
   at System.Threading.Tasks.Task.ExecuteWithThreadLocal(Task& currentTaskSlot)
--- End of stack trace from previous location where exception was thrown ---
   at System.Runtime.ExceptionServices.ExceptionDispatchInfo.Throw()
   at System.Runtime.CompilerServices.TaskAwaiter.HandleNonSuccessAndDebuggerNotification(Task task)
   at System.Runtime.CompilerServices.TaskAwaiter`1.GetResult()
   at Microsoft.EntityFrameworkCore.Storage.Internal.RelationalCommand.<ExecuteAsync>d__17.MoveNext()
ClientConnectionId:affcb151-ecb9-4436-9e5f-b93a31a5e079
Error Number:242,State:3,Class:16
2018-04-27 16:16:35.273 +03:00 [Error] An exception occurred in the database while saving changes for context type '"IQCare.HTS.Infrastructure.HtsDbContext"'."
""Microsoft.EntityFrameworkCore.DbUpdateException: An error occurred while updating the entries. See the inner exception for details. ---> System.Data.SqlClient.SqlException: The conversion of a datetime2 data type to a datetime data type resulted in an out-of-range value.
The statement has been terminated.
   at System.Data.SqlClient.SqlCommand.<>c.<ExecuteDbDataReaderAsync>b__108_0(Task`1 result)
   at System.Threading.Tasks.ContinuationResultTaskFromResultTask`2.InnerInvoke()
   at System.Threading.ExecutionContext.Run(ExecutionContext executionContext, ContextCallback callback, Object state)
   at System.Threading.Tasks.Task.ExecuteWithThreadLocal(Task& currentTaskSlot)
--- End of stack trace from previous location where exception was thrown ---
   at System.Runtime.ExceptionServices.ExceptionDispatchInfo.Throw()
   at System.Runtime.CompilerServices.TaskAwaiter.HandleNonSuccessAndDebuggerNotification(Task task)
   at System.Runtime.CompilerServices.TaskAwaiter`1.GetResult()
   at Microsoft.EntityFrameworkCore.Storage.Internal.RelationalCommand.<ExecuteAsync>d__17.MoveNext()
--- End of stack trace from previous location where exception was thrown ---
   at System.Runtime.ExceptionServices.ExceptionDispatchInfo.Throw()
   at System.Runtime.CompilerServices.TaskAwaiter.HandleNonSuccessAndDebuggerNotification(Task task)
   at System.Runtime.CompilerServices.TaskAwaiter`1.GetResult()
   at Microsoft.EntityFrameworkCore.Update.ReaderModificationCommandBatch.<ExecuteAsync>d__32.MoveNext()
   --- End of inner exception stack trace ---
   at Microsoft.EntityFrameworkCore.Update.ReaderModificationCommandBatch.<ExecuteAsync>d__32.MoveNext()
--- End of stack trace from previous location where exception was thrown ---
   at System.Runtime.ExceptionServices.ExceptionDispatchInfo.Throw()
   at System.Runtime.CompilerServices.TaskAwaiter.HandleNonSuccessAndDebuggerNotification(Task task)
   at Microsoft.EntityFrameworkCore.Update.Internal.BatchExecutor.<ExecuteAsync>d__10.MoveNext()
--- End of stack trace from previous location where exception was thrown ---
   at System.Runtime.ExceptionServices.ExceptionDispatchInfo.Throw()
   at System.Runtime.CompilerServices.TaskAwaiter.HandleNonSuccessAndDebuggerNotification(Task task)
   at Microsoft.EntityFrameworkCore.Storage.Internal.SqlServerExecutionStrategy.<ExecuteAsync>d__7`2.MoveNext()
--- End of stack trace from previous location where exception was thrown ---
   at System.Runtime.ExceptionServices.ExceptionDispatchInfo.Throw()
   at System.Runtime.CompilerServices.TaskAwaiter.HandleNonSuccessAndDebuggerNotification(Task task)
   at System.Runtime.CompilerServices.TaskAwaiter`1.GetResult()
   at Microsoft.EntityFrameworkCore.ChangeTracking.Internal.StateManager.<SaveChangesAsync>d__61.MoveNext()
--- End of stack trace from previous location where exception was thrown ---
   at System.Runtime.ExceptionServices.ExceptionDispatchInfo.Throw()
   at System.Runtime.CompilerServices.TaskAwaiter.HandleNonSuccessAndDebuggerNotification(Task task)
   at System.Runtime.CompilerServices.TaskAwaiter`1.GetResult()
   at Microsoft.EntityFrameworkCore.ChangeTracking.Internal.StateManager.<SaveChangesAsync>d__59.MoveNext()
--- End of stack trace from previous location where exception was thrown ---
   at System.Runtime.ExceptionServices.ExceptionDispatchInfo.Throw()
   at System.Runtime.CompilerServices.TaskAwaiter.HandleNonSuccessAndDebuggerNotification(Task task)
   at System.Runtime.CompilerServices.TaskAwaiter`1.GetResult()
   at Microsoft.EntityFrameworkCore.DbContext.<SaveChangesAsync>d__48.MoveNext()"
Microsoft.EntityFrameworkCore.DbUpdateException: An error occurred while updating the entries. See the inner exception for details. ---> System.Data.SqlClient.SqlException: The conversion of a datetime2 data type to a datetime data type resulted in an out-of-range value.
The statement has been terminated.
   at System.Data.SqlClient.SqlCommand.<>c.<ExecuteDbDataReaderAsync>b__108_0(Task`1 result)
   at System.Threading.Tasks.ContinuationResultTaskFromResultTask`2.InnerInvoke()
   at System.Threading.ExecutionContext.Run(ExecutionContext executionContext, ContextCallback callback, Object state)
   at System.Threading.Tasks.Task.ExecuteWithThreadLocal(Task& currentTaskSlot)
--- End of stack trace from previous location where exception was thrown ---
   at System.Runtime.ExceptionServices.ExceptionDispatchInfo.Throw()
   at System.Runtime.CompilerServices.TaskAwaiter.HandleNonSuccessAndDebuggerNotification(Task task)
   at System.Runtime.CompilerServices.TaskAwaiter`1.GetResult()
   at Microsoft.EntityFrameworkCore.Storage.Internal.RelationalCommand.<ExecuteAsync>d__17.MoveNext()
--- End of stack trace from previous location where exception was thrown ---
   at System.Runtime.ExceptionServices.ExceptionDispatchInfo.Throw()
   at System.Runtime.CompilerServices.TaskAwaiter.HandleNonSuccessAndDebuggerNotification(Task task)
   at System.Runtime.CompilerServices.TaskAwaiter`1.GetResult()
   at Microsoft.EntityFrameworkCore.Update.ReaderModificationCommandBatch.<ExecuteAsync>d__32.MoveNext()
   --- End of inner exception stack trace ---
   at Microsoft.EntityFrameworkCore.Update.ReaderModificationCommandBatch.<ExecuteAsync>d__32.MoveNext()
--- End of stack trace from previous location where exception was thrown ---
   at System.Runtime.ExceptionServices.ExceptionDispatchInfo.Throw()
   at System.Runtime.CompilerServices.TaskAwaiter.HandleNonSuccessAndDebuggerNotification(Task task)
   at Microsoft.EntityFrameworkCore.Update.Internal.BatchExecutor.<ExecuteAsync>d__10.MoveNext()
--- End of stack trace from previous location where exception was thrown ---
   at System.Runtime.ExceptionServices.ExceptionDispatchInfo.Throw()
   at System.Runtime.CompilerServices.TaskAwaiter.HandleNonSuccessAndDebuggerNotification(Task task)
   at Microsoft.EntityFrameworkCore.Storage.Internal.SqlServerExecutionStrategy.<ExecuteAsync>d__7`2.MoveNext()
--- End of stack trace from previous location where exception was thrown ---
   at System.Runtime.ExceptionServices.ExceptionDispatchInfo.Throw()
   at System.Runtime.CompilerServices.TaskAwaiter.HandleNonSuccessAndDebuggerNotification(Task task)
   at System.Runtime.CompilerServices.TaskAwaiter`1.GetResult()
   at Microsoft.EntityFrameworkCore.ChangeTracking.Internal.StateManager.<SaveChangesAsync>d__61.MoveNext()
--- End of stack trace from previous location where exception was thrown ---
   at System.Runtime.ExceptionServices.ExceptionDispatchInfo.Throw()
   at System.Runtime.CompilerServices.TaskAwaiter.HandleNonSuccessAndDebuggerNotification(Task task)
   at System.Runtime.CompilerServices.TaskAwaiter`1.GetResult()
   at Microsoft.EntityFrameworkCore.ChangeTracking.Internal.StateManager.<SaveChangesAsync>d__59.MoveNext()
--- End of stack trace from previous location where exception was thrown ---
   at System.Runtime.ExceptionServices.ExceptionDispatchInfo.Throw()
   at System.Runtime.CompilerServices.TaskAwaiter.HandleNonSuccessAndDebuggerNotification(Task task)
   at System.Runtime.CompilerServices.TaskAwaiter`1.GetResult()
   at Microsoft.EntityFrameworkCore.DbContext.<SaveChangesAsync>d__48.MoveNext()
2018-04-27 16:16:35.440 +03:00 [Error] An error occurred while updating the entries. See the inner exception for details.
2018-04-27 16:17:23.581 +03:00 [Error] Failed executing DbCommand ("79"ms) [Parameters=["@p0='?', @p1='?', @p2='?', @p3='?', @p4='?', @p5='?', @p6='?', @p7='?', @p8='?', @p9='?', @p10='?', @p11='?'"], CommandType='Text', CommandTimeout='30']"
""SET NOCOUNT ON;
DECLARE @inserted0 TABLE ([Id] int, [_Position] [int]);
MERGE [ClientDisability] USING (
VALUES (@p0, @p1, @p2, @p3, @p4, @p5, 0),
(@p6, @p7, @p8, @p9, @p10, @p11, 1)) AS i ([CreateDate], [CreatedBy], [DeleteFlag], [DisabilityId], [PatientEncounterId], [PersonId], _Position) ON 1=0
WHEN NOT MATCHED THEN
INSERT ([CreateDate], [CreatedBy], [DeleteFlag], [DisabilityId], [PatientEncounterId], [PersonId])
VALUES (i.[CreateDate], i.[CreatedBy], i.[DeleteFlag], i.[DisabilityId], i.[PatientEncounterId], i.[PersonId])
OUTPUT INSERTED.[Id], i._Position
INTO @inserted0;

SELECT [t].[Id] FROM [ClientDisability] t
INNER JOIN @inserted0 i ON ([t].[Id] = [i].[Id])
ORDER BY [i].[_Position];"
System.Data.SqlClient.SqlException (0x80131904): The conversion of a datetime2 data type to a datetime data type resulted in an out-of-range value.
The statement has been terminated.
   at System.Data.SqlClient.SqlCommand.<>c.<ExecuteDbDataReaderAsync>b__108_0(Task`1 result)
   at System.Threading.Tasks.ContinuationResultTaskFromResultTask`2.InnerInvoke()
   at System.Threading.ExecutionContext.Run(ExecutionContext executionContext, ContextCallback callback, Object state)
   at System.Threading.Tasks.Task.ExecuteWithThreadLocal(Task& currentTaskSlot)
--- End of stack trace from previous location where exception was thrown ---
   at System.Runtime.ExceptionServices.ExceptionDispatchInfo.Throw()
   at System.Runtime.CompilerServices.TaskAwaiter.HandleNonSuccessAndDebuggerNotification(Task task)
   at System.Runtime.CompilerServices.TaskAwaiter`1.GetResult()
   at Microsoft.EntityFrameworkCore.Storage.Internal.RelationalCommand.<ExecuteAsync>d__17.MoveNext()
ClientConnectionId:affcb151-ecb9-4436-9e5f-b93a31a5e079
Error Number:242,State:3,Class:16
2018-04-27 16:17:23.618 +03:00 [Error] An exception occurred in the database while saving changes for context type '"IQCare.HTS.Infrastructure.HtsDbContext"'."
""Microsoft.EntityFrameworkCore.DbUpdateException: An error occurred while updating the entries. See the inner exception for details. ---> System.Data.SqlClient.SqlException: The conversion of a datetime2 data type to a datetime data type resulted in an out-of-range value.
The statement has been terminated.
   at System.Data.SqlClient.SqlCommand.<>c.<ExecuteDbDataReaderAsync>b__108_0(Task`1 result)
   at System.Threading.Tasks.ContinuationResultTaskFromResultTask`2.InnerInvoke()
   at System.Threading.ExecutionContext.Run(ExecutionContext executionContext, ContextCallback callback, Object state)
   at System.Threading.Tasks.Task.ExecuteWithThreadLocal(Task& currentTaskSlot)
--- End of stack trace from previous location where exception was thrown ---
   at System.Runtime.ExceptionServices.ExceptionDispatchInfo.Throw()
   at System.Runtime.CompilerServices.TaskAwaiter.HandleNonSuccessAndDebuggerNotification(Task task)
   at System.Runtime.CompilerServices.TaskAwaiter`1.GetResult()
   at Microsoft.EntityFrameworkCore.Storage.Internal.RelationalCommand.<ExecuteAsync>d__17.MoveNext()
--- End of stack trace from previous location where exception was thrown ---
   at System.Runtime.ExceptionServices.ExceptionDispatchInfo.Throw()
   at System.Runtime.CompilerServices.TaskAwaiter.HandleNonSuccessAndDebuggerNotification(Task task)
   at System.Runtime.CompilerServices.TaskAwaiter`1.GetResult()
   at Microsoft.EntityFrameworkCore.Update.ReaderModificationCommandBatch.<ExecuteAsync>d__32.MoveNext()
   --- End of inner exception stack trace ---
   at Microsoft.EntityFrameworkCore.Update.ReaderModificationCommandBatch.<ExecuteAsync>d__32.MoveNext()
--- End of stack trace from previous location where exception was thrown ---
   at System.Runtime.ExceptionServices.ExceptionDispatchInfo.Throw()
   at System.Runtime.CompilerServices.TaskAwaiter.HandleNonSuccessAndDebuggerNotification(Task task)
   at Microsoft.EntityFrameworkCore.Update.Internal.BatchExecutor.<ExecuteAsync>d__10.MoveNext()
--- End of stack trace from previous location where exception was thrown ---
   at System.Runtime.ExceptionServices.ExceptionDispatchInfo.Throw()
   at System.Runtime.CompilerServices.TaskAwaiter.HandleNonSuccessAndDebuggerNotification(Task task)
   at Microsoft.EntityFrameworkCore.Storage.Internal.SqlServerExecutionStrategy.<ExecuteAsync>d__7`2.MoveNext()
--- End of stack trace from previous location where exception was thrown ---
   at System.Runtime.ExceptionServices.ExceptionDispatchInfo.Throw()
   at System.Runtime.CompilerServices.TaskAwaiter.HandleNonSuccessAndDebuggerNotification(Task task)
   at System.Runtime.CompilerServices.TaskAwaiter`1.GetResult()
   at Microsoft.EntityFrameworkCore.ChangeTracking.Internal.StateManager.<SaveChangesAsync>d__61.MoveNext()
--- End of stack trace from previous location where exception was thrown ---
   at System.Runtime.ExceptionServices.ExceptionDispatchInfo.Throw()
   at System.Runtime.CompilerServices.TaskAwaiter.HandleNonSuccessAndDebuggerNotification(Task task)
   at System.Runtime.CompilerServices.TaskAwaiter`1.GetResult()
   at Microsoft.EntityFrameworkCore.ChangeTracking.Internal.StateManager.<SaveChangesAsync>d__59.MoveNext()
--- End of stack trace from previous location where exception was thrown ---
   at System.Runtime.ExceptionServices.ExceptionDispatchInfo.Throw()
   at System.Runtime.CompilerServices.TaskAwaiter.HandleNonSuccessAndDebuggerNotification(Task task)
   at System.Runtime.CompilerServices.TaskAwaiter`1.GetResult()
   at Microsoft.EntityFrameworkCore.DbContext.<SaveChangesAsync>d__48.MoveNext()"
Microsoft.EntityFrameworkCore.DbUpdateException: An error occurred while updating the entries. See the inner exception for details. ---> System.Data.SqlClient.SqlException: The conversion of a datetime2 data type to a datetime data type resulted in an out-of-range value.
The statement has been terminated.
   at System.Data.SqlClient.SqlCommand.<>c.<ExecuteDbDataReaderAsync>b__108_0(Task`1 result)
   at System.Threading.Tasks.ContinuationResultTaskFromResultTask`2.InnerInvoke()
   at System.Threading.ExecutionContext.Run(ExecutionContext executionContext, ContextCallback callback, Object state)
   at System.Threading.Tasks.Task.ExecuteWithThreadLocal(Task& currentTaskSlot)
--- End of stack trace from previous location where exception was thrown ---
   at System.Runtime.ExceptionServices.ExceptionDispatchInfo.Throw()
   at System.Runtime.CompilerServices.TaskAwaiter.HandleNonSuccessAndDebuggerNotification(Task task)
   at System.Runtime.CompilerServices.TaskAwaiter`1.GetResult()
   at Microsoft.EntityFrameworkCore.Storage.Internal.RelationalCommand.<ExecuteAsync>d__17.MoveNext()
--- End of stack trace from previous location where exception was thrown ---
   at System.Runtime.ExceptionServices.ExceptionDispatchInfo.Throw()
   at System.Runtime.CompilerServices.TaskAwaiter.HandleNonSuccessAndDebuggerNotification(Task task)
   at System.Runtime.CompilerServices.TaskAwaiter`1.GetResult()
   at Microsoft.EntityFrameworkCore.Update.ReaderModificationCommandBatch.<ExecuteAsync>d__32.MoveNext()
   --- End of inner exception stack trace ---
   at Microsoft.EntityFrameworkCore.Update.ReaderModificationCommandBatch.<ExecuteAsync>d__32.MoveNext()
--- End of stack trace from previous location where exception was thrown ---
   at System.Runtime.ExceptionServices.ExceptionDispatchInfo.Throw()
   at System.Runtime.CompilerServices.TaskAwaiter.HandleNonSuccessAndDebuggerNotification(Task task)
   at Microsoft.EntityFrameworkCore.Update.Internal.BatchExecutor.<ExecuteAsync>d__10.MoveNext()
--- End of stack trace from previous location where exception was thrown ---
   at System.Runtime.ExceptionServices.ExceptionDispatchInfo.Throw()
   at System.Runtime.CompilerServices.TaskAwaiter.HandleNonSuccessAndDebuggerNotification(Task task)
   at Microsoft.EntityFrameworkCore.Storage.Internal.SqlServerExecutionStrategy.<ExecuteAsync>d__7`2.MoveNext()
--- End of stack trace from previous location where exception was thrown ---
   at System.Runtime.ExceptionServices.ExceptionDispatchInfo.Throw()
   at System.Runtime.CompilerServices.TaskAwaiter.HandleNonSuccessAndDebuggerNotification(Task task)
   at System.Runtime.CompilerServices.TaskAwaiter`1.GetResult()
   at Microsoft.EntityFrameworkCore.ChangeTracking.Internal.StateManager.<SaveChangesAsync>d__61.MoveNext()
--- End of stack trace from previous location where exception was thrown ---
   at System.Runtime.ExceptionServices.ExceptionDispatchInfo.Throw()
   at System.Runtime.CompilerServices.TaskAwaiter.HandleNonSuccessAndDebuggerNotification(Task task)
   at System.Runtime.CompilerServices.TaskAwaiter`1.GetResult()
   at Microsoft.EntityFrameworkCore.ChangeTracking.Internal.StateManager.<SaveChangesAsync>d__59.MoveNext()
--- End of stack trace from previous location where exception was thrown ---
   at System.Runtime.ExceptionServices.ExceptionDispatchInfo.Throw()
   at System.Runtime.CompilerServices.TaskAwaiter.HandleNonSuccessAndDebuggerNotification(Task task)
   at System.Runtime.CompilerServices.TaskAwaiter`1.GetResult()
   at Microsoft.EntityFrameworkCore.DbContext.<SaveChangesAsync>d__48.MoveNext()
2018-04-27 16:46:55.264 +03:00 [Error] Failed executing DbCommand ("177"ms) [Parameters=["@p0='?', @p1='?', @p2='?' (Size = 4000), @p3='?', @p4='?', @p5='?', @p6='?', @p7='?' (Size = 4000), @p8='?', @p9='?', @p10='?', @p11='?', @p12='?', @p13='?', @p14='?', @p15='?'"], CommandType='Text', CommandTimeout='30']"
""SET NOCOUNT ON;
INSERT INTO [HtsEncounter] ([Id], [CoupleDiscordant], [EncounterRemarks], [EncounterType], [EverSelfTested], [EverTested], [FinalResultGiven], [GeoLocation], [MonthSinceSelfTest], [MonthsSinceLastTest], [PatientEncounterID], [PersonId], [ProviderId], [TestEntryPoint], [TestedAs], [TestingStrategy])
VALUES (@p0, @p1, @p2, @p3, @p4, @p5, @p6, @p7, @p8, @p9, @p10, @p11, @p12, @p13, @p14, @p15);"
System.Data.SqlClient.SqlException (0x80131904): Cannot insert explicit value for identity column in table 'HtsEncounter' when IDENTITY_INSERT is set to OFF.
   at System.Data.SqlClient.SqlCommand.<>c.<ExecuteDbDataReaderAsync>b__108_0(Task`1 result)
   at System.Threading.Tasks.ContinuationResultTaskFromResultTask`2.InnerInvoke()
   at System.Threading.ExecutionContext.Run(ExecutionContext executionContext, ContextCallback callback, Object state)
   at System.Threading.Tasks.Task.ExecuteWithThreadLocal(Task& currentTaskSlot)
--- End of stack trace from previous location where exception was thrown ---
   at System.Runtime.ExceptionServices.ExceptionDispatchInfo.Throw()
   at System.Runtime.CompilerServices.TaskAwaiter.HandleNonSuccessAndDebuggerNotification(Task task)
   at System.Runtime.CompilerServices.TaskAwaiter`1.GetResult()
   at Microsoft.EntityFrameworkCore.Storage.Internal.RelationalCommand.<ExecuteAsync>d__17.MoveNext()
ClientConnectionId:4ea98732-962b-4ea5-ae05-f8d00a01c000
Error Number:544,State:1,Class:16
2018-04-27 16:46:55.424 +03:00 [Error] An exception occurred in the database while saving changes for context type '"IQCare.HTS.Infrastructure.HtsDbContext"'."
""Microsoft.EntityFrameworkCore.DbUpdateException: An error occurred while updating the entries. See the inner exception for details. ---> System.Data.SqlClient.SqlException: Cannot insert explicit value for identity column in table 'HtsEncounter' when IDENTITY_INSERT is set to OFF.
   at System.Data.SqlClient.SqlCommand.<>c.<ExecuteDbDataReaderAsync>b__108_0(Task`1 result)
   at System.Threading.Tasks.ContinuationResultTaskFromResultTask`2.InnerInvoke()
   at System.Threading.ExecutionContext.Run(ExecutionContext executionContext, ContextCallback callback, Object state)
   at System.Threading.Tasks.Task.ExecuteWithThreadLocal(Task& currentTaskSlot)
--- End of stack trace from previous location where exception was thrown ---
   at System.Runtime.ExceptionServices.ExceptionDispatchInfo.Throw()
   at System.Runtime.CompilerServices.TaskAwaiter.HandleNonSuccessAndDebuggerNotification(Task task)
   at System.Runtime.CompilerServices.TaskAwaiter`1.GetResult()
   at Microsoft.EntityFrameworkCore.Storage.Internal.RelationalCommand.<ExecuteAsync>d__17.MoveNext()
--- End of stack trace from previous location where exception was thrown ---
   at System.Runtime.ExceptionServices.ExceptionDispatchInfo.Throw()
   at System.Runtime.CompilerServices.TaskAwaiter.HandleNonSuccessAndDebuggerNotification(Task task)
   at System.Runtime.CompilerServices.TaskAwaiter`1.GetResult()
   at Microsoft.EntityFrameworkCore.Update.ReaderModificationCommandBatch.<ExecuteAsync>d__32.MoveNext()
   --- End of inner exception stack trace ---
   at Microsoft.EntityFrameworkCore.Update.ReaderModificationCommandBatch.<ExecuteAsync>d__32.MoveNext()
--- End of stack trace from previous location where exception was thrown ---
   at System.Runtime.ExceptionServices.ExceptionDispatchInfo.Throw()
   at System.Runtime.CompilerServices.TaskAwaiter.HandleNonSuccessAndDebuggerNotification(Task task)
   at Microsoft.EntityFrameworkCore.Update.Internal.BatchExecutor.<ExecuteAsync>d__10.MoveNext()
--- End of stack trace from previous location where exception was thrown ---
   at System.Runtime.ExceptionServices.ExceptionDispatchInfo.Throw()
   at System.Runtime.CompilerServices.TaskAwaiter.HandleNonSuccessAndDebuggerNotification(Task task)
   at Microsoft.EntityFrameworkCore.Storage.Internal.SqlServerExecutionStrategy.<ExecuteAsync>d__7`2.MoveNext()
--- End of stack trace from previous location where exception was thrown ---
   at System.Runtime.ExceptionServices.ExceptionDispatchInfo.Throw()
   at System.Runtime.CompilerServices.TaskAwaiter.HandleNonSuccessAndDebuggerNotification(Task task)
   at System.Runtime.CompilerServices.TaskAwaiter`1.GetResult()
   at Microsoft.EntityFrameworkCore.ChangeTracking.Internal.StateManager.<SaveChangesAsync>d__61.MoveNext()
--- End of stack trace from previous location where exception was thrown ---
   at System.Runtime.ExceptionServices.ExceptionDispatchInfo.Throw()
   at System.Runtime.CompilerServices.TaskAwaiter.HandleNonSuccessAndDebuggerNotification(Task task)
   at System.Runtime.CompilerServices.TaskAwaiter`1.GetResult()
   at Microsoft.EntityFrameworkCore.ChangeTracking.Internal.StateManager.<SaveChangesAsync>d__59.MoveNext()
--- End of stack trace from previous location where exception was thrown ---
   at System.Runtime.ExceptionServices.ExceptionDispatchInfo.Throw()
   at System.Runtime.CompilerServices.TaskAwaiter.HandleNonSuccessAndDebuggerNotification(Task task)
   at System.Runtime.CompilerServices.TaskAwaiter`1.GetResult()
   at Microsoft.EntityFrameworkCore.DbContext.<SaveChangesAsync>d__48.MoveNext()"
Microsoft.EntityFrameworkCore.DbUpdateException: An error occurred while updating the entries. See the inner exception for details. ---> System.Data.SqlClient.SqlException: Cannot insert explicit value for identity column in table 'HtsEncounter' when IDENTITY_INSERT is set to OFF.
   at System.Data.SqlClient.SqlCommand.<>c.<ExecuteDbDataReaderAsync>b__108_0(Task`1 result)
   at System.Threading.Tasks.ContinuationResultTaskFromResultTask`2.InnerInvoke()
   at System.Threading.ExecutionContext.Run(ExecutionContext executionContext, ContextCallback callback, Object state)
   at System.Threading.Tasks.Task.ExecuteWithThreadLocal(Task& currentTaskSlot)
--- End of stack trace from previous location where exception was thrown ---
   at System.Runtime.ExceptionServices.ExceptionDispatchInfo.Throw()
   at System.Runtime.CompilerServices.TaskAwaiter.HandleNonSuccessAndDebuggerNotification(Task task)
   at System.Runtime.CompilerServices.TaskAwaiter`1.GetResult()
   at Microsoft.EntityFrameworkCore.Storage.Internal.RelationalCommand.<ExecuteAsync>d__17.MoveNext()
--- End of stack trace from previous location where exception was thrown ---
   at System.Runtime.ExceptionServices.ExceptionDispatchInfo.Throw()
   at System.Runtime.CompilerServices.TaskAwaiter.HandleNonSuccessAndDebuggerNotification(Task task)
   at System.Runtime.CompilerServices.TaskAwaiter`1.GetResult()
   at Microsoft.EntityFrameworkCore.Update.ReaderModificationCommandBatch.<ExecuteAsync>d__32.MoveNext()
   --- End of inner exception stack trace ---
   at Microsoft.EntityFrameworkCore.Update.ReaderModificationCommandBatch.<ExecuteAsync>d__32.MoveNext()
--- End of stack trace from previous location where exception was thrown ---
   at System.Runtime.ExceptionServices.ExceptionDispatchInfo.Throw()
   at System.Runtime.CompilerServices.TaskAwaiter.HandleNonSuccessAndDebuggerNotification(Task task)
   at Microsoft.EntityFrameworkCore.Update.Internal.BatchExecutor.<ExecuteAsync>d__10.MoveNext()
--- End of stack trace from previous location where exception was thrown ---
   at System.Runtime.ExceptionServices.ExceptionDispatchInfo.Throw()
   at System.Runtime.CompilerServices.TaskAwaiter.HandleNonSuccessAndDebuggerNotification(Task task)
   at Microsoft.EntityFrameworkCore.Storage.Internal.SqlServerExecutionStrategy.<ExecuteAsync>d__7`2.MoveNext()
--- End of stack trace from previous location where exception was thrown ---
   at System.Runtime.ExceptionServices.ExceptionDispatchInfo.Throw()
   at System.Runtime.CompilerServices.TaskAwaiter.HandleNonSuccessAndDebuggerNotification(Task task)
   at System.Runtime.CompilerServices.TaskAwaiter`1.GetResult()
   at Microsoft.EntityFrameworkCore.ChangeTracking.Internal.StateManager.<SaveChangesAsync>d__61.MoveNext()
--- End of stack trace from previous location where exception was thrown ---
   at System.Runtime.ExceptionServices.ExceptionDispatchInfo.Throw()
   at System.Runtime.CompilerServices.TaskAwaiter.HandleNonSuccessAndDebuggerNotification(Task task)
   at System.Runtime.CompilerServices.TaskAwaiter`1.GetResult()
   at Microsoft.EntityFrameworkCore.ChangeTracking.Internal.StateManager.<SaveChangesAsync>d__59.MoveNext()
--- End of stack trace from previous location where exception was thrown ---
   at System.Runtime.ExceptionServices.ExceptionDispatchInfo.Throw()
   at System.Runtime.CompilerServices.TaskAwaiter.HandleNonSuccessAndDebuggerNotification(Task task)
   at System.Runtime.CompilerServices.TaskAwaiter`1.GetResult()
   at Microsoft.EntityFrameworkCore.DbContext.<SaveChangesAsync>d__48.MoveNext()
2018-04-27 16:47:34.669 +03:00 [Error] An error occurred while updating the entries. See the inner exception for details.
2018-04-27 16:47:59.797 +03:00 [Error] Failed executing DbCommand ("87"ms) [Parameters=["@p0='?', @p1='?', @p2='?' (Size = 4000), @p3='?', @p4='?', @p5='?', @p6='?', @p7='?' (Size = 4000), @p8='?', @p9='?', @p10='?', @p11='?', @p12='?', @p13='?', @p14='?', @p15='?'"], CommandType='Text', CommandTimeout='30']"
""SET NOCOUNT ON;
INSERT INTO [HtsEncounter] ([Id], [CoupleDiscordant], [EncounterRemarks], [EncounterType], [EverSelfTested], [EverTested], [FinalResultGiven], [GeoLocation], [MonthSinceSelfTest], [MonthsSinceLastTest], [PatientEncounterID], [PersonId], [ProviderId], [TestEntryPoint], [TestedAs], [TestingStrategy])
VALUES (@p0, @p1, @p2, @p3, @p4, @p5, @p6, @p7, @p8, @p9, @p10, @p11, @p12, @p13, @p14, @p15);"
System.Data.SqlClient.SqlException (0x80131904): Cannot insert explicit value for identity column in table 'HtsEncounter' when IDENTITY_INSERT is set to OFF.
   at System.Data.SqlClient.SqlCommand.<>c.<ExecuteDbDataReaderAsync>b__108_0(Task`1 result)
   at System.Threading.Tasks.ContinuationResultTaskFromResultTask`2.InnerInvoke()
   at System.Threading.ExecutionContext.Run(ExecutionContext executionContext, ContextCallback callback, Object state)
   at System.Threading.Tasks.Task.ExecuteWithThreadLocal(Task& currentTaskSlot)
--- End of stack trace from previous location where exception was thrown ---
   at System.Runtime.ExceptionServices.ExceptionDispatchInfo.Throw()
   at System.Runtime.CompilerServices.TaskAwaiter.HandleNonSuccessAndDebuggerNotification(Task task)
   at System.Runtime.CompilerServices.TaskAwaiter`1.GetResult()
   at Microsoft.EntityFrameworkCore.Storage.Internal.RelationalCommand.<ExecuteAsync>d__17.MoveNext()
ClientConnectionId:4ea98732-962b-4ea5-ae05-f8d00a01c000
Error Number:544,State:1,Class:16
2018-04-27 16:47:59.842 +03:00 [Error] An exception occurred in the database while saving changes for context type '"IQCare.HTS.Infrastructure.HtsDbContext"'."
""Microsoft.EntityFrameworkCore.DbUpdateException: An error occurred while updating the entries. See the inner exception for details. ---> System.Data.SqlClient.SqlException: Cannot insert explicit value for identity column in table 'HtsEncounter' when IDENTITY_INSERT is set to OFF.
   at System.Data.SqlClient.SqlCommand.<>c.<ExecuteDbDataReaderAsync>b__108_0(Task`1 result)
   at System.Threading.Tasks.ContinuationResultTaskFromResultTask`2.InnerInvoke()
   at System.Threading.ExecutionContext.Run(ExecutionContext executionContext, ContextCallback callback, Object state)
   at System.Threading.Tasks.Task.ExecuteWithThreadLocal(Task& currentTaskSlot)
--- End of stack trace from previous location where exception was thrown ---
   at System.Runtime.ExceptionServices.ExceptionDispatchInfo.Throw()
   at System.Runtime.CompilerServices.TaskAwaiter.HandleNonSuccessAndDebuggerNotification(Task task)
   at System.Runtime.CompilerServices.TaskAwaiter`1.GetResult()
   at Microsoft.EntityFrameworkCore.Storage.Internal.RelationalCommand.<ExecuteAsync>d__17.MoveNext()
--- End of stack trace from previous location where exception was thrown ---
   at System.Runtime.ExceptionServices.ExceptionDispatchInfo.Throw()
   at System.Runtime.CompilerServices.TaskAwaiter.HandleNonSuccessAndDebuggerNotification(Task task)
   at System.Runtime.CompilerServices.TaskAwaiter`1.GetResult()
   at Microsoft.EntityFrameworkCore.Update.ReaderModificationCommandBatch.<ExecuteAsync>d__32.MoveNext()
   --- End of inner exception stack trace ---
   at Microsoft.EntityFrameworkCore.Update.ReaderModificationCommandBatch.<ExecuteAsync>d__32.MoveNext()
--- End of stack trace from previous location where exception was thrown ---
   at System.Runtime.ExceptionServices.ExceptionDispatchInfo.Throw()
   at System.Runtime.CompilerServices.TaskAwaiter.HandleNonSuccessAndDebuggerNotification(Task task)
   at Microsoft.EntityFrameworkCore.Update.Internal.BatchExecutor.<ExecuteAsync>d__10.MoveNext()
--- End of stack trace from previous location where exception was thrown ---
   at System.Runtime.ExceptionServices.ExceptionDispatchInfo.Throw()
   at System.Runtime.CompilerServices.TaskAwaiter.HandleNonSuccessAndDebuggerNotification(Task task)
   at Microsoft.EntityFrameworkCore.Storage.Internal.SqlServerExecutionStrategy.<ExecuteAsync>d__7`2.MoveNext()
--- End of stack trace from previous location where exception was thrown ---
   at System.Runtime.ExceptionServices.ExceptionDispatchInfo.Throw()
   at System.Runtime.CompilerServices.TaskAwaiter.HandleNonSuccessAndDebuggerNotification(Task task)
   at System.Runtime.CompilerServices.TaskAwaiter`1.GetResult()
   at Microsoft.EntityFrameworkCore.ChangeTracking.Internal.StateManager.<SaveChangesAsync>d__61.MoveNext()
--- End of stack trace from previous location where exception was thrown ---
   at System.Runtime.ExceptionServices.ExceptionDispatchInfo.Throw()
   at System.Runtime.CompilerServices.TaskAwaiter.HandleNonSuccessAndDebuggerNotification(Task task)
   at System.Runtime.CompilerServices.TaskAwaiter`1.GetResult()
   at Microsoft.EntityFrameworkCore.ChangeTracking.Internal.StateManager.<SaveChangesAsync>d__59.MoveNext()
--- End of stack trace from previous location where exception was thrown ---
   at System.Runtime.ExceptionServices.ExceptionDispatchInfo.Throw()
   at System.Runtime.CompilerServices.TaskAwaiter.HandleNonSuccessAndDebuggerNotification(Task task)
   at System.Runtime.CompilerServices.TaskAwaiter`1.GetResult()
   at Microsoft.EntityFrameworkCore.DbContext.<SaveChangesAsync>d__48.MoveNext()"
Microsoft.EntityFrameworkCore.DbUpdateException: An error occurred while updating the entries. See the inner exception for details. ---> System.Data.SqlClient.SqlException: Cannot insert explicit value for identity column in table 'HtsEncounter' when IDENTITY_INSERT is set to OFF.
   at System.Data.SqlClient.SqlCommand.<>c.<ExecuteDbDataReaderAsync>b__108_0(Task`1 result)
   at System.Threading.Tasks.ContinuationResultTaskFromResultTask`2.InnerInvoke()
   at System.Threading.ExecutionContext.Run(ExecutionContext executionContext, ContextCallback callback, Object state)
   at System.Threading.Tasks.Task.ExecuteWithThreadLocal(Task& currentTaskSlot)
--- End of stack trace from previous location where exception was thrown ---
   at System.Runtime.ExceptionServices.ExceptionDispatchInfo.Throw()
   at System.Runtime.CompilerServices.TaskAwaiter.HandleNonSuccessAndDebuggerNotification(Task task)
   at System.Runtime.CompilerServices.TaskAwaiter`1.GetResult()
   at Microsoft.EntityFrameworkCore.Storage.Internal.RelationalCommand.<ExecuteAsync>d__17.MoveNext()
--- End of stack trace from previous location where exception was thrown ---
   at System.Runtime.ExceptionServices.ExceptionDispatchInfo.Throw()
   at System.Runtime.CompilerServices.TaskAwaiter.HandleNonSuccessAndDebuggerNotification(Task task)
   at System.Runtime.CompilerServices.TaskAwaiter`1.GetResult()
   at Microsoft.EntityFrameworkCore.Update.ReaderModificationCommandBatch.<ExecuteAsync>d__32.MoveNext()
   --- End of inner exception stack trace ---
   at Microsoft.EntityFrameworkCore.Update.ReaderModificationCommandBatch.<ExecuteAsync>d__32.MoveNext()
--- End of stack trace from previous location where exception was thrown ---
   at System.Runtime.ExceptionServices.ExceptionDispatchInfo.Throw()
   at System.Runtime.CompilerServices.TaskAwaiter.HandleNonSuccessAndDebuggerNotification(Task task)
   at Microsoft.EntityFrameworkCore.Update.Internal.BatchExecutor.<ExecuteAsync>d__10.MoveNext()
--- End of stack trace from previous location where exception was thrown ---
   at System.Runtime.ExceptionServices.ExceptionDispatchInfo.Throw()
   at System.Runtime.CompilerServices.TaskAwaiter.HandleNonSuccessAndDebuggerNotification(Task task)
   at Microsoft.EntityFrameworkCore.Storage.Internal.SqlServerExecutionStrategy.<ExecuteAsync>d__7`2.MoveNext()
--- End of stack trace from previous location where exception was thrown ---
   at System.Runtime.ExceptionServices.ExceptionDispatchInfo.Throw()
   at System.Runtime.CompilerServices.TaskAwaiter.HandleNonSuccessAndDebuggerNotification(Task task)
   at System.Runtime.CompilerServices.TaskAwaiter`1.GetResult()
   at Microsoft.EntityFrameworkCore.ChangeTracking.Internal.StateManager.<SaveChangesAsync>d__61.MoveNext()
--- End of stack trace from previous location where exception was thrown ---
   at System.Runtime.ExceptionServices.ExceptionDispatchInfo.Throw()
   at System.Runtime.CompilerServices.TaskAwaiter.HandleNonSuccessAndDebuggerNotification(Task task)
   at System.Runtime.CompilerServices.TaskAwaiter`1.GetResult()
   at Microsoft.EntityFrameworkCore.ChangeTracking.Internal.StateManager.<SaveChangesAsync>d__59.MoveNext()
--- End of stack trace from previous location where exception was thrown ---
   at System.Runtime.ExceptionServices.ExceptionDispatchInfo.Throw()
   at System.Runtime.CompilerServices.TaskAwaiter.HandleNonSuccessAndDebuggerNotification(Task task)
   at System.Runtime.CompilerServices.TaskAwaiter`1.GetResult()
   at Microsoft.EntityFrameworkCore.DbContext.<SaveChangesAsync>d__48.MoveNext()
2018-04-27 16:48:40.684 +03:00 [Error] An error occurred while updating the entries. See the inner exception for details.
